<?xml version="1.0"?>
<robot name="origins">

    <link name="base">
        <inertial>
            <mass value="1."/>
        </inertial>
        <collision>
            <origin xyz="0 0 0.05"/>
            <geometry>
                <box size="0.5 0.5 0.1"/>
            </geometry>
        </collision>
    </link>

    <link name="tower">
        <inertial>
            <mass value="1."/>
        </inertial>
        <collision>
            <geometry>
                <box size="0.1 0.1 1.0"/>
            </geometry>
        </collision>
    </link>

    <joint name="rz" type="revolute">
        <parent link="base"/>
        <child link="tower"/>
        <origin xyz="0 0 0.5" rpy="0 0 1.5708"/>
        <axis xyz="0 0 1"/>
    </joint>

    <link name="jib">
        <inertial>
            <mass value="1.0"/>
        </inertial>
        <collision>
            <geometry>
                <box size="1.0 0.1 0.1"/>
            </geometry>
        </collision>
    </link>

    <joint name="tz" type="prismatic">
        <parent link="tower"/>
        <child link="jib"/>
        <origin xyz="0.3 0 0." rpy="0 0 0"/>
        <axis xyz="0 0 1"/>
    </joint>

    <link name="trolley">
        <inertial>
            <mass value="1.0"/>
        </inertial>
        <visual>
            <origin xyz="0 0 -0.17"/>
            <geometry>
                <sphere radius="0.14"/>
            </geometry>
        </visual>
        <collision>
            <origin xyz="0 0 -0.17"/>
            <geometry>
                <box size="0.15 0.15 0.2"/>
            </geometry>
        </collision>
    </link>

    <joint name="ty" type="prismatic">
        <parent link="jib"/>
        <child link="trolley"/>
        <origin xyz="0.2 0 0." rpy="0 0 0"/>
        <axis xyz="1 0 0"/>
    </joint>
</robot>
